Workbook

Sheet Итог
E4: номер круга
C5: Номер мишени | E5: 1 | K5: 2 | Y5: 3 | AE5: 4 | AK5: 5 | AQ5: 6 | AW5: 7 | BG5: 8 | BM5: 9
E6: ЦР НАР 1 | G6: ЦР НАР 2 | I6: ЦР ОБЩ | K6: ЦР НАР 1 | M6: ЦР НАР 2 | O6: ЦР НАР 3 | Q6: ЦР НАР 4 | S6: ЦР НАР 5 | U6: ЦР НАР 6 | W6: ЦР ОБЩ | Y6: ЦР НАР 1 | AA6: ЦР НАР 2 | AC6: ЦР ОБЩ | AE6: ЦР НАР 1 | AG6: ЦР НАР 2 | AI6: ЦР ОБЩ | AK6: ЦР НАР 1 | AM6: ЦР НАР 2 | AO6: ЦР ОБЩ | AQ6: ЦР НАР 1 | AS6: ЦР НАР 2 | AU6: ЦР ОБЩ | AW6: ЦР НАР 1 | AY6: ЦР НАР 2 | BA6: ЦР НАР 3 | BC6: ЦР НАР 4 | BE6: ЦР ОБЩ | BG6: ЦР НАР 1 | BI6: ЦР НАР 2 | BK6: ЦР ОБЩ | BM6: ЦР НАР 1 | BO6: ЦР НАР 2 | BQ6: ЦР ОБЩ
C7: Координаты | E7: х | F7: z | G7: х | H7: z | I7: х | J7: z | K7: х | L7: z | M7: х | N7: z | O7: х | P7: z | Q7: х | R7: z | S7: х | T7: z | U7: х | V7: z | W7: х | X7: z | Y7: х | Z7: z | AA7: х | AB7: z | AC7: х | AD7: z | AE7: х | AF7: z | AG7: х | AH7: z | AI7: х | AJ7: z | AK7: х | AL7: z | AM7: х | AN7: z | AO7: х | AP7: z | AQ7: х | AR7: z | AS7: х | AT7: z | AU7: х | AV7: z | AW7: х | AX7: z | AY7: х | AZ7: z | BA7: х | BB7: z | BC7: х | BD7: z | BE7: х | BF7: z | BG7: х | BH7: z | BI7: х | BJ7: z | BK7: х | BL7: z | BM7: х | BN7: z | BO7: х | BP7: z | BQ7: х | BR7: z
C8: 243 | E8: ='243-1 '!I12 -> 82.838852 | F8: ='243-1 '!J12 -> -6.9653993 | G8: ='243-1 '!I38 -> 78.880306 | H8: ='243-1 '!J38 -> -116.91867 | I8: ='243-1 '!I4 -> 80.859579 | J8: ='243-1 '!J4 -> -61.942037 | K8: ='243-2'!I12 -> 56.136428 | L8: ='243-2'!J12 -> -72.515277 | M8: ='243-2'!I38 -> 36.312578 | N8: ='243-2'!J38 -> -27.177382 | W8: ='243-2'!I4 -> 46.224503 | X8: ='243-2'!J4 -> -49.846329 | Y8: ='243-3 '!I12 -> 79.181425 | Z8: ='243-3 '!J12 -> 101.31866 | AA8: ='243-3 '!I38 -> 56.343637 | AB8: ='243-3 '!J38 -> 48.153307 | AC8: ='243-3 '!I4 -> 67.762531 | AD8: ='243-3 '!J4 -> 74.735983 | AE8: ='243-4'!I12 -> 50.936895 | AF8: ='243-4'!J12 -> 14.803887 | AG8: ='243-4'!I38 -> 62.626482 | AH8: ='243-4'!J38 -> -81.011521 | AI8: ='243-4'!I4 -> 56.781688 | AJ8: ='243-4'!J4 -> -33.103817
C10: 242 | E10: ='242-1'!I12 -> -6.3901188 | F10: ='242-1'!J12 -> 101.17652 | I10: ='242-1'!I4 -> -6.3901188 | J10: ='242-1'!J4 -> 101.17652 | K10: ='242-2'!I12 -> 35.283843 | L10: ='242-2'!J12 -> -44.4854 | W10: ='242-2'!I4 -> 35.283843 | X10: ='242-2'!J4 -> -44.4854 | Y10: ='242-3'!$I$12 -> 31.623979 | Z10: ='242-3'!J12 -> -17.198034 | AA10: ='242-3'!$I$38 -> 55.259485 | AB10: ='242-3'!J38 -> -42.43549 | AC10: ='242-3'!$I$4 -> 43.441732 | AD10: ='242-3'!J4 -> -29.816762
C12: 241 | E12: ='241-1'!I12 -> 77.768861 | F12: ='241-1'!J12 -> -27.004946 | G12: ='241-1'!I38 -> 117.24127 | H12: ='241-1'!J38 -> 23.392764 | I12: ='241-1'!I4 -> 97.505065 | J12: ='241-1'!J4 -> -1.8060911 | K12: ='241-2__6 ракет'!I12 -> 170.78303 | L12: ='241-2__6 ракет'!J12 -> -21.532868 | M12: ='241-2__6 ракет'!I38 -> 106.54218 | N12: ='241-2__6 ракет'!J38 -> 23.722547 | O12: ='241-2__6 ракет'!I64 -> 58.132835 | P12: ='241-2__6 ракет'!J64 -> 25.599138 | Q12: ='241-2__6 ракет'!I90 -> 56.452577 | R12: ='241-2__6 ракет'!J90 -> 91.476286 | S12: ='241-2__6 ракет'!AI12 -> 36.772205 | T12: ='241-2__6 ракет'!AJ12 -> -120.81213 | U12: ='241-2__6 ракет'!AI38 -> 82.049096 | V12: ='241-2__6 ракет'!AJ38 -> -117.80354 | W12: ='241-2__6 ракет'!I4 -> 85.121986 | X12: ='241-2__6 ракет'!J4 -> -19.891763
C14: 240 | AQ14: ='240-6'!I12 -> 138.73912 | AR14: ='240-6'!J12 -> -11.244532 | AU14: ='240-6'!I4 -> 138.73912 | AV14: ='240-6'!J4 -> -11.244532 | AW14: ='240-7__4 ркеты'!$I$12 -> 116.14276 | AX14: ='240-7__4 ркеты'!$J$12 -> 19.205126 | AY14: ='240-7__4 ркеты'!$I$38 -> 67.287428 | AZ14: ='240-7__4 ркеты'!$J$38 -> 18.996543 | BA14: ='240-7__4 ркеты'!$I$64 -> 32.11137 | BB14: ='240-7__4 ркеты'!$J$64 -> -90.543462 | BC14: ='240-7__4 ркеты'!$I$90 -> 112.25361 | BD14: ='240-7__4 ркеты'!$J$90 -> -82.33211 | BE14: ='240-7__4 ркеты'!$I$4 -> 81.948793 | BF14: ='240-7__4 ркеты'!$J$4 -> -33.668476 | BG14: ='240-8'!I12 -> 144.1354 | BH14: ='240-8'!J12 -> -28.705682 | BK14: ='240-8'!I4 -> 144.1354 | BL14: ='240-8'!J4 -> -28.705682 | BM14: ='240-9'!$I$12 -> 187.28076 | BN14: ='240-9'!$J$12 -> 3.773773 | BO14: ='240-9'!$I$38 -> 125.60642 | BP14: ='240-9'!$J$38 -> -113.02771 | BQ14: ='240-9'!$I$4 -> 156.44359 | BR14: ='240-9'!$J$4 -> -54.62697
E79: расстояние между кругами по Х | H79: 200
D80: расстояние мжду линейками зет | H80: 500
C82: Номер мишени | E82: 1 | K82: 2 | Y82: 3 | AE82: 4 | AK82: 5 | AQ82: 6 | AW82: 7 | BG82: 8 | BM82: 9
E83: ЦР НАР 1 | G83: ЦР НАР 2 | I83: ЦР ОБЩ | K83: ЦР НАР 1 | M83: ЦР НАР 2 | O83: ЦР НАР 3 | Q83: ЦР НАР 4 | S83: ЦР НАР 5 | U83: ЦР НАР 6 | W83: ЦР ОБЩ | Y83: ЦР НАР 1 | AA83: ЦР НАР 2 | AC83: ЦР ОБЩ | AE83: ЦР НАР 1 | AG83: ЦР НАР 2 | AI83: ЦР ОБЩ | AK83: ЦР НАР 1 | AM83: ЦР НАР 2 | AO83: ЦР ОБЩ | AQ83: ЦР НАР 1 | AS83: ЦР НАР 2 | AU83: ЦР ОБЩ | AW83: ЦР НАР 1 | AY83: ЦР НАР 2 | BA83: ЦР НАР 3 | BC83: ЦР НАР 4 | BE83: ЦР ОБЩ | BG83: ЦР НАР 1 | BI83: ЦР НАР 2 | BK83: ЦР ОБЩ | BM83: ЦР НАР 1 | BO83: ЦР НАР 2 | BQ83: ЦР ОБЩ
C84: Координаты | E84: х | F84: z | G84: х | H84: z | I84: х | J84: z | K84: х | L84: z | M84: х | N84: z | O84: х | P84: z | Q84: х | R84: z | S84: х | T84: z | U84: х | V84: z | W84: х | X84: z | Y84: х | Z84: z | AA84: х | AB84: z | AC84: х | AD84: z | AE84: х | AF84: z | AG84: х | AH84: z | AI84: х | AJ84: z | AK84: х | AL84: z | AM84: х | AN84: z | AO84: х | AP84: z | AQ84: х | AR84: z | AS84: х | AT84: z | AU84: х | AV84: z | AW84: х | AX84: z | AY84: х | AZ84: z | BA84: х | BB84: z | BC84: х | BD84: z | BE84: х | BF84: z | BG84: х | BH84: z | BI84: х | BJ84: z | BK84: х | BL84: z | BM84: х | BN84: z | BO84: х | BP84: z | BQ84: х | BR84: z
C85: 243 | E85: =E8 -> 82.838852 | F85: =F8-$H$79*3 -> -606.9654 | G85: =G8 -> 78.880306 | H85: =H8-$H$79*3 -> -716.91867 | I85: =I8 -> 80.859579 | J85: =J8-$H$79*3 -> -661.94204 | K85: =K8 -> 56.136428 | L85: =L8-$H$79*2 -> -472.51528 | M85: =M8 -> 36.312578 | N85: =N8-$H$79*2 -> -427.17738 | W85: =W8 -> 46.224503 | X85: =X8-$H$79*2 -> -449.84633 | Y85: =Y8 -> 79.181425 | Z85: =Z8-$H$79 -> -98.681341 | AA85: =AA8 -> 56.343637 | AB85: =AB8-$H$79 -> -151.84669 | AC85: =AC8 -> 67.762531 | AD85: =AD8-$H$79 -> -125.26402 | AE85: =AE8 -> 50.936895 | AF85: =AF8 -> 14.803887 | AG85: =AG8 -> 62.626482 | AH85: =AH8 -> -81.011521 | AI85: =AI8 -> 56.781688 | AJ85: =AJ8 -> -33.103817
C87: 242 | E87: =E10+$H$80 -> 493.60988 | F87: =F10-$H$79*3 -> -498.82348 | I87: =I10-$H$80 -> -506.39012 | J87: =J10-$H$79*3 -> -498.82348 | K87: =K10+$H$80 -> 535.28384 | L87: =L10-$H$79*2 -> -444.4854 | W87: =W10+$H$80 -> 535.28384 | X87: =X10-$H$80 -> -544.4854 | Y87: =Y10+$H$80 -> 531.62398 | Z87: =Z10-$H$79 -> -217.19803 | AA87: =AA10+$H$80 -> 555.25949 | AB87: =AB10-$H$79 -> -242.43549 | AC87: =AC10+$H$80 -> 543.44173 | AD87: =AD10-$H$79 -> -229.81676
C89: 241 | E89: =E12+$H$80*2 -> 1077.7689 | F89: =F12-$H$79*3 -> -627.00495 | G89: =G12+$H$80*2 -> 1117.2413 | H89: =H12-$H$79*3 -> -576.60724 | I89: =I12+$H$80*2 -> 1097.5051 | J89: =J12-$H$79*3 -> -601.80609 | K89: =K12+$H$80*2 -> 1170.783 | L89: =L12-$H$79*2 -> -421.53287 | M89: =M12+$H$80*2 -> 1106.5422 | N89: =N12-$H$79*2 -> -376.27745 | O89: =O12+$H$80*2 -> 1058.1328 | P89: =P12-$H$79*2 -> -374.40086 | Q89: =Q12+$H$80*2 -> 1056.4526 | R89: =R12-$H$79*2 -> -308.52371 | S89: =S12+$H$80*2 -> 1036.7722 | T89: =T12-$H$79*2 -> -520.81213 | U89: =U12+$H$80*2 -> 1082.0491 | V89: =V12-$H$79*2 -> -517.80354 | W89: =W12+$H$80*2 -> 1085.122 | X89: =X12-$H$79*2 -> -419.89176
C91: 240 | AQ91: =AQ14+$H$80*3 -> 1638.7391 | AR91: =AR14+$H$79*2 -> 388.75547 | AU91: =AU14+$H$80*3 -> 1638.7391 | AV91: =AV14+$H$79*2 -> 388.75547 | AW91: =AW14+$H$80*3 -> 1616.1428 | AX91: =AX14+$H$79*3 -> 619.20513 | AY91: =AY14+$H$80*3 -> 1567.2874 | AZ91: =AZ14+$H$79*3 -> 618.99654 | BA91: =BA14+$H$80*3 -> 1532.1114 | BB91: =BB14+$H$79*3 -> 509.45654 | BC91: =BC14+$H$80*3 -> 1612.2536 | BD91: =BD14+$H$79*3 -> 517.66789 | BE91: =BE14+$H$80*3 -> 1581.9488 | BF91: =BF14+$H$79*3 -> 566.33152 | BG91: =BG14+$H$80*3 -> 1644.1354 | BH91: =BH14+$H$79*4 -> 771.29432 | BK91: =BK14+$H$80*3 -> 1644.1354 | BL91: =BL14+$H$79*4 -> 771.29432 | BM91: =BM14+$H$80*3 -> 1687.2808 | BN91: =BN14+$H$79*5 -> 1003.7738 | BO91: =BO14+$H$80*3 -> 1625.6064 | BP91: =BP14+$H$79*5 -> 886.97229 | BQ91: =BQ14+$H$80*3 -> 1656.4436 | BR91: =BR14+$H$79*5 -> 945.37303

Sheet условия пусков
B2: № захода | C2: Условия пусков | H2: Номер цели и результат | I2: Найдено НАР | J2: Результаты пусков | BX2: 240/8
C3: Канал | D3: Vпр | E3: Нпус | F3: Дпус | G3: Тангаж | J3: центр рассеивания КОБЭ НАР 1 | L3: центр рассеивания КОБЭ НАР 2 | N3: центр рассеивания НАР | BX3: Канал | BY3: Vпр | BZ3: Нпус | CA3: Дпус | CB3: центр рассеивания КОБЭ НАР 1 | CD3: центр рассеивания КОБЭ НАР 2 | CF3: центр рассеивания НАР
C4: ЦУ | D4: км/ч | E4: м | F4: м | G4: град | J4: х | K4: z | L4: х | M4: z | N4: x | O4: z | BX4: ЦУ | BY4: км/ч | BZ4: м | CA4: м | CB4: х | CC4: z | CD4: х | CE4: z | CF4: x | CG4: z
B5: 1 | C5: нвгц | D5: 203 | E5: 522 | F5: 3.1 | G5: 0 | H5: 242-1 | I5: 1
B6: 2 | C6: НВГЦ | D6: 193 | E6: 515 | F6: 3.4 | G6: 0 | H6: 242-2 | I6: 1 | J6: 82.84 | K6: -6.97 | L6: 78.88 | M6: -116.92 | N6: 80.86 | O6: -61.94 | BX6: ЦУ ОПС | BY6: 225 | BZ6: 300 | CA6: 4500 | CB6: =#REF! -> #REF! | CC6: =#REF! -> #REF!
B7: 3 | C7: НВГЦ | D7: 182 | E7: 469 | F7: 3.9 | G7: -13 | H7: 242-3 | J7: 51.73 | K7: -45.75 | L7: 43.79 | M7: -59.74 | N7: 47.76 | O7: -52.74
B9: 4 | C9: ОПС | D9: 194 | E9: 488 | F9: 3.2 | G9: -15 | H9: 242-4 | J9: 101.32 | K9: 79,18 | L9: 80.86 | M9: 48.15 | N9: 67.76 | O9: 74,74;
B11: 5 | C11: ОПС | D11: 217 | E11: 281 | F11: 4.2 | G11: -14 | H11: 243-1 | I11: 2
B13: 6 | C13: НВГЦ | D13: 202 | E13: 285 | F13: 4.1 | G13: -14 | H13: 243-2 | I13: 2
B15: 7 | C15: НВГЦ | D15: 202 | E15: 270 | F15: 4.2 | G15: -13 | H15: 243-3 | I15: 2
B17: 8 | C17: НВГЦ | D17: 196 | E17: 278 | F17: 4.2 | G17: -15 | H17: 243-1
B19: 9 | C19: НВГЦ | D19: 164 | E19: 322 | F19: 5.2 | G19: -19 | H19: 243-4 | I19: 2
B21: 10 | C21: НВГЦ | D21: 185 | E21: 309 | F21: 5 | G21: -17 | H21: 240-6 | I21: 1
B23: 11 | C23: ОПС | D23: 175 | E23: 317 | F23: 5 | G23: -20 | H23: 240-7 | I23: 4
B25: 12 | C25: НВГЦ | D25: 163 | E25: 292 | F25: 5.2 | G25: -19 | H25: 240-8 | I25: 1
B27: 13 | C27: НВГЦ | D27: 175 | E27: 544 | F27: 5.1 | G27: -18 | H27: 240-9 | I27: 2
B29: 14 | C29: НВГЦ | D29: 180 | E29: 526 | F29: 4.9 | G29: -18 | H29: 241-1 | I29: 2
B31: 15 | C31: ОПС | D31: 191 | E31: 495 | F31: 5.2 | G31: -18 | H31: 241-2 | I31: 6
B33: 16 | C33: ОПС | D33: 191 | E33: 518 | F33: 5.1 | G33: -17 | H33: 241-3 | I33: 2
B35: 17 | C35: НВГЦ | D35: 195 | E35: 794 | F35: 5.3 | G35: -15 | H35: 241-4
B37: 18 | C37: НВГЦ | D37: 188 | E37: 833 | F37: 5.1 | G37: -17 | H37: 241-5
B39: 19 | C39: НВГЦ | D39: 167 | E39: 344 | F39: 5.2 | G39: -18 | H39: 241-6
B41: 20 | C41: ОПС | D41: 195 | E41: 378 | F41: 5.1 | G41: -16 | H41: 241-7
B43: 21
B45: 22
B47: 23
I49: =SUM(I5:I48) -> 28

Sheet 240-6
B1: 240-6
B2: Канал | C2: курс | D2: Vпр | E2: Нпус | F2: Дпус | I2: Центр рассеивания НАР
B3: ЦУ | D3: км/ч | E3: м | F3: м
B4: НВГЦ/ЛЦУ | C4: 270 | I4: =IF(E6,((I12+I38)/2),I12) -> 138.73912 | J4: =IF(E6,((J12+J38)/2),J12) -> -11.244532
B5: Число КОБЭ | C5: Всего | D5: НАР 1 | E5: НАР 2 | I5: x | J5: z
C6: 48 | D6: 23 | E6: 0
A10: КОБЭ от НАР 1
A11: номер п/п | B11: азимут | C11: дальность | D11: Азимут за вычетом боевого курса | E11: градусы | F11: минуты (в сотых градуса) | G11: х | H11: z | I11: Мх | J11: Мz | K11: Хт-Мх | L11: Zт-Мz | M11: (Хт-Мх)*2 | N11: (Zт-Мz)*2 | O11: N-1 | P11: Σ(Хт-Мх)*2 | Q11: Σ(Zт-Мz)*2 | R11: (Σ(Хт-Мх)*2)/(N-1) | S11: (Σ(Zт-Мz)*2)/(N-1) | T11: Сигма X | U11: Сигма Z | V11: σX*σZ | W11: СКО КОБЭ
A12: 1 | B12: 263.1 | C12: 164 | D12: =IF(B12,B12-$C$4," ") -> -6.9 | E12: =IF(B12,INT(D12)," ") -> -7 | F12: =IF(B12,((D12-E12)/60*100)," ") -> 0.16666667 | G12: =IF(B12,C12*COS(PI()/180*(E12+F12))," ") -> 162.83502 | H12: =IF(B12,(C12*SIN(PI()/180*(E12+F12)))," ") -> -19.512988 | I12: =SUM(G12:G34)/D6 -> 138.73912 | J12: =SUM(H12:H34)/D6 -> -11.244532 | K12: =IF(B12,SUM(G12,-$I$12)," ") -> 24.095895 | L12: =IF(B12,SUM(H12,-$J$12)," ") -> -8.2684554 | M12: =IF(B12,POWER(K12,2)," ") -> 580.61217 | N12: =IF(B12,POWER(L12,2)," ") -> 68.367354 | O12: =D6-1 -> 22 | P12: =SUM(M12:M35) -> 27577.856 | Q12: =SUM(N12:N35) -> 1669.5147 | R12: =PRODUCT(P12,1/$O$12) -> 1253.5389 | S12: =PRODUCT(Q12,1/$O$12) -> 75.887033 | T12: =SQRT(R12) -> 35.405351 | U12: =SQRT(S12) -> 8.7113163 | V12: =PRODUCT(T12:U12) -> 308.42722 | W12: =SQRT(V12) -> 17.562096
A13: 2 | B13: 266.1 | C13: 258 | D13: =IF(B13,B13-$C$4," ") -> -3.9 | E13: =IF(B13,INT(D13)," ") -> -4 | F13: =IF(B13,((D13-E13)/60*100)," ") -> 0.16666667 | G13: =IF(B13,C13*COS(PI()/180*(E13+F13))," ") -> 257.42279 | H13: =IF(B13,(C13*SIN(PI()/180*(E13+F13)))," ") -> -17.248432 | K13: =IF(B13,SUM(G13,-$I$12)," ") -> 118.68366 | L13: =IF(B13,SUM(H13,-$J$12)," ") -> -6.0038994 | M13: =IF(B13,POWER(K13,2)," ") -> 14085.812 | N13: =IF(B13,POWER(L13,2)," ") -> 36.046808
A14: 3 | B14: 267.3 | C14: 160 | D14: =IF(B14,B14-$C$4," ") -> -2.7 | E14: =IF(B14,INT(D14)," ") -> -3 | F14: =IF(B14,((D14-E14)/60*100)," ") -> 0.5 | G14: =IF(B14,C14*COS(PI()/180*(E14+F14))," ") -> 159.84772 | H14: =IF(B14,(C14*SIN(PI()/180*(E14+F14)))," ") -> -6.979102 | K14: =IF(B14,SUM(G14,-$I$12)," ") -> 21.108592 | L14: =IF(B14,SUM(H14,-$J$12)," ") -> 4.2654303 | M14: =IF(B14,POWER(K14,2)," ") -> 445.57266 | N14: =IF(B14,POWER(L14,2)," ") -> 18.193896
A15: 4 | B15: 268.2 | C15: 166 | D15: =IF(B15,B15-$C$4," ") -> -1.8 | E15: =IF(B15,INT(D15)," ") -> -2 | F15: =IF(B15,((D15-E15)/60*100)," ") -> 0.33333333 | G15: =IF(B15,C15*COS(PI()/180*(E15+F15))," ") -> 165.92977 | H15: =IF(B15,(C15*SIN(PI()/180*(E15+F15)))," ") -> -4.8280633 | K15: =IF(B15,SUM(G15,-$I$12)," ") -> 27.19065 | L15: =IF(B15,SUM(H15,-$J$12)," ") -> 6.416469 | M15: =IF(B15,POWER(K15,2)," ") -> 739.33146 | N15: =IF(B15,POWER(L15,2)," ") -> 41.171074
A16: 5 | B16: 267.45 | C16: 156 | D16: =IF(B16,B16-$C$4," ") -> -2.55 | E16: =IF(B16,INT(D16)," ") -> -3 | F16: =IF(B16,((D16-E16)/60*100)," ") -> 0.75 | G16: =IF(B16,C16*COS(PI()/180*(E16+F16))," ") -> 155.87973 | H16: =IF(B16,(C16*SIN(PI()/180*(E16+F16)))," ") -> -6.1245313 | K16: =IF(B16,SUM(G16,-$I$12)," ") -> 17.140606 | L16: =IF(B16,SUM(H16,-$J$12)," ") -> 5.1200011 | M16: =IF(B16,POWER(K16,2)," ") -> 293.80038 | N16: =IF(B16,POWER(L16,2)," ") -> 26.214411
A17: 6 | B17: 266.5 | C17: 154 | D17: =IF(B17,B17-$C$4," ") -> -3.5 | E17: =IF(B17,INT(D17)," ") -> -4 | F17: =IF(B17,((D17-E17)/60*100)," ") -> 0.83333333 | G17: =IF(B17,C17*COS(PI()/180*(E17+F17))," ") -> 153.76485 | H17: =IF(B17,(C17*SIN(PI()/180*(E17+F17)))," ") -> -8.5070564 | K17: =IF(B17,SUM(G17,-$I$12)," ") -> 15.025729 | L17: =IF(B17,SUM(H17,-$J$12)," ") -> 2.7374759 | M17: =IF(B17,POWER(K17,2)," ") -> 225.77254 | N17: =IF(B17,POWER(L17,2)," ") -> 7.4937741
A18: 7 | B18: 266.3 | C18: 156 | D18: =IF(B18,B18-$C$4," ") -> -3.7 | E18: =IF(B18,INT(D18)," ") -> -4 | F18: =IF(B18,((D18-E18)/60*100)," ") -> 0.5 | G18: =IF(B18,C18*COS(PI()/180*(E18+F18))," ") -> 155.70903 | H18: =IF(B18,(C18*SIN(PI()/180*(E18+F18)))," ") -> -9.5235722 | K18: =IF(B18,SUM(G18,-$I$12)," ") -> 16.969905 | L18: =IF(B18,SUM(H18,-$J$12)," ") -> 1.7209601 | M18: =IF(B18,POWER(K18,2)," ") -> 287.97768 | N18: =IF(B18,POWER(L18,2)," ") -> 2.9617038
A19: 8 | B19: 264.55 | C19: 156 | D19: =IF(B19,B19-$C$4," ") -> -5.45 | E19: =IF(B19,INT(D19)," ") -> -6 | F19: =IF(B19,((D19-E19)/60*100)," ") -> 0.91666667 | G19: =IF(B19,C19*COS(PI()/180*(E19+F19))," ") -> 155.38643 | H19: =IF(B19,(C19*SIN(PI()/180*(E19+F19)))," ") -> -13.822311 | K19: =IF(B19,SUM(G19,-$I$12)," ") -> 16.64731 | L19: =IF(B19,SUM(H19,-$J$12)," ") -> -2.5777785 | M19: =IF(B19,POWER(K19,2)," ") -> 277.13293 | N19: =IF(B19,POWER(L19,2)," ") -> 6.644942
A20: 9 | B20: 262.2 | C20: 144 | D20: =IF(B20,B20-$C$4," ") -> -7.8 | E20: =IF(B20,INT(D20)," ") -> -8 | F20: =IF(B20,((D20-E20)/60*100)," ") -> 0.33333333 | G20: =IF(B20,C20*COS(PI()/180*(E20+F20))," ") -> 142.71278 | H20: =IF(B20,(C20*SIN(PI()/180*(E20+F20)))," ") -> -19.210987 | K20: =IF(B20,SUM(G20,-$I$12)," ") -> 3.9736579 | L20: =IF(B20,SUM(H20,-$J$12)," ") -> -7.9664547 | M20: =IF(B20,POWER(K20,2)," ") -> 15.789957 | N20: =IF(B20,POWER(L20,2)," ") -> 63.464401
A21: 10 | B21: 268 | C21: 146 | D21: =IF(B21,B21-$C$4," ") -> -2 | E21: =IF(B21,INT(D21)," ") -> -2 | F21: =IF(B21,((D21-E21)/60*100)," ") -> 0 | G21: =IF(B21,C21*COS(PI()/180*(E21+F21))," ") -> 145.91106 | H21: =IF(B21,(C21*SIN(PI()/180*(E21+F21)))," ") -> -5.0953265 | K21: =IF(B21,SUM(G21,-$I$12)," ") -> 7.1719373 | L21: =IF(B21,SUM(H21,-$J$12)," ") -> 6.1492058 | M21: =IF(B21,POWER(K21,2)," ") -> 51.436684 | N21: =IF(B21,POWER(L21,2)," ") -> 37.812732
A22: 11 | B22: 270.35 | C22: 140 | D22: =IF(B22,B22-$C$4," ") -> 0.35 | E22: =IF(B22,INT(D22)," ") -> 0 | F22: =IF(B22,((D22-E22)/60*100)," ") -> 0.58333333 | G22: =IF(B22,C22*COS(PI()/180*(E22+F22))," ") -> 139.99274 | H22: =IF(B22,(C22*SIN(PI()/180*(E22+F22)))," ") -> 1.4253276 | K22: =IF(B22,SUM(G22,-$I$12)," ") -> 1.2536208 | L22: =IF(B22,SUM(H22,-$J$12)," ") -> 12.66986 | M22: =IF(B22,POWER(K22,2)," ") -> 1.571565 | N22: =IF(B22,POWER(L22,2)," ") -> 160.52535
A23: 12 | B23: 265.5 | C23: 138 | D23: =IF(B23,B23-$C$4," ") -> -4.5 | E23: =IF(B23,INT(D23)," ") -> -5 | F23: =IF(B23,((D23-E23)/60*100)," ") -> 0.83333333 | G23: =IF(B23,C23*COS(PI()/180*(E23+F23))," ") -> 137.63525 | H23: =IF(B23,(C23*SIN(PI()/180*(E23+F23)))," ") -> -10.0268 | K23: =IF(B23,SUM(G23,-$I$12)," ") -> -1.103869 | L23: =IF(B23,SUM(H23,-$J$12)," ") -> 1.2177324 | M23: =IF(B23,POWER(K23,2)," ") -> 1.2185267 | N23: =IF(B23,POWER(L23,2)," ") -> 1.4828721
A24: 13 | B24: 264.05 | C24: 138 | D24: =IF(B24,B24-$C$4," ") -> -5.95 | E24: =IF(B24,INT(D24)," ") -> -6 | F24: =IF(B24,((D24-E24)/60*100)," ") -> 0.083333333 | G24: =IF(B24,C24*COS(PI()/180*(E24+F24))," ") -> 137.26486 | H24: =IF(B24,(C24*SIN(PI()/180*(E24+F24)))," ") -> -14.225299 | K24: =IF(B24,SUM(G24,-$I$12)," ") -> -1.4742669 | L24: =IF(B24,SUM(H24,-$J$12)," ") -> -2.9807671 | M24: =IF(B24,POWER(K24,2)," ") -> 2.1734628 | N24: =IF(B24,POWER(L24,2)," ") -> 8.8849725
... A34: 23 | B34: 263.45 | C34: 70 | D34: =IF(B34,B34-$C$4," ") -> -6.55 | E34: =IF(B34,INT(D34)," ") -> -7 | F34: =IF(B34,((D34-E34)/60*100)," ") -> 0.75 | G34: =IF(B34,C34*COS(PI()/180*(E34+F34))," ") -> 69.583944 | H34: =IF(B34,(C34*SIN(PI()/180*(E34+F34)))," ") -> -7.6206812 | K34: =IF(B34,SUM(G34,-$I$12)," ") -> -69.15518 | L34: =IF(B34,SUM(H34,-$J$12)," ") -> 3.6238511 | M34: =IF(B34,POWER(K34,2)," ") -> 4782.4389 | N34: =IF(B34,POWER(L34,2)," ") -> 13.132297
A35: 24 | D35: =IF(B35,B35-$C$4," ") | E35: =IF(B35,INT(D35)," ") | F35: =IF(B35,((D35-E35)/60*100)," ") | G35: =IF(B35,C35*COS(PI()/180*(E35+F35))," ") | H35: =IF(B35,(C35*SIN(PI()/180*(E35+F35)))," ") | K35: =IF(B35,SUM(G35,-$I$12)," ") | L35: =IF(B35,SUM(H35,-$J$12)," ") | M35: =IF(B35,POWER(K35,2)," ") | N35: =IF(B35,POWER(L35,2)," ")
A36: КОБЭ от НАР 2
A37: номер п/п | B37: азимут | C37: дальность | D37: Азимут за вычетом боевого курса | E37: градусы | F37: минуты (в сотых градуса) | G37: х | H37: z | I37: Мх | J37: Мz | K37: Хт-Мх | L37: Zт-Мz | M37: (Хт-Мх)*2 | N37: (Zт-Мz)*2 | O37: N-1 | P37: Σ(Хт-Мх)*2 | Q37: Σ(Zт-Мz)*2 | R37: (Σ(Хт-Мх)*2)/(N-1) | S37: (Σ(Zт-Мz)*2)/(N-1) | T37: Сигма X | U37: Сигма Z | V37: σX*σZ | W37: СКО КОБЭ
A38: 1 | D38: =IF(B38,B38-$C$4," ") | E38: =IF(B38,INT(D38)," ") | F38: =IF(B38,((D38-E38)/60*100)," ") | G38: =IF(B38,C38*COS(PI()/180*(E38+F38))," ") | H38: =IF(B38,(C38*SIN(PI()/180*(E38+F38)))," ") | I38: =SUM(G38:G61)/E6 -> #DIV/0! | J38: =SUM(H38:H61)/E6 -> #DIV/0! | K38: =IF(B38,SUM(G38,-$I$12)," ") | L38: =IF(B38,SUM(H38,-$J$12)," ") | M38: =IF(B38,POWER(K38,2)," ") | N38: =IF(B38,POWER(L38,2)," ") | O38: =E6-1 -> -1 | P38: =SUM(M38:M61) -> 0 | Q38: =SUM(N38:N61) -> 0 | R38: =PRODUCT(P38,1/$O$38) -> 0 | S38: =PRODUCT(Q38,1/$O$38) -> 0 | T38: =SQRT(R38) -> 0 | U38: =SQRT(S38) -> 0 | V38: =PRODUCT(T38:U38) -> 0 | W38: =SQRT(V38) -> 0
A39: 2 | D39: =IF(B39,B39-$C$4," ") | E39: =IF(B39,INT(D39)," ") | F39: =IF(B39,((D39-E39)/60*100)," ") | G39: =IF(B39,C39*COS(PI()/180*(E39+F39))," ") | H39: =IF(B39,(C39*SIN(PI()/180*(E39+F39)))," ") | K39: =IF(B39,SUM(G39,-$I$12)," ") | L39: =IF(B39,SUM(H39,-$J$12)," ") | M39: =IF(B39,POWER(K39,2)," ") | N39: =IF(B39,POWER(L39,2)," ")
A40: 3 | D40: =IF(B40,B40-$C$4," ") | E40: =IF(B40,INT(D40)," ") | F40: =IF(B40,((D40-E40)/60*100)," ") | G40: =IF(B40,C40*COS(PI()/180*(E40+F40))," ") | H40: =IF(B40,(C40*SIN(PI()/180*(E40+F40)))," ") | K40: =IF(B40,SUM(G40,-$I$12)," ") | L40: =IF(B40,SUM(H40,-$J$12)," ") | M40: =IF(B40,POWER(K40,2)," ") | N40: =IF(B40,POWER(L40,2)," ")
A41: 4 | D41: =IF(B41,B41-$C$4," ") | E41: =IF(B41,INT(D41)," ") | F41: =IF(B41,((D41-E41)/60*100)," ") | G41: =IF(B41,C41*COS(PI()/180*(E41+F41))," ") | H41: =IF(B41,(C41*SIN(PI()/180*(E41+F41)))," ") | K41: =IF(B41,SUM(G41,-$I$12)," ") | L41: =IF(B41,SUM(H41,-$J$12)," ") | M41: =IF(B41,POWER(K41,2)," ") | N41: =IF(B41,POWER(L41,2)," ")
A42: 5 | D42: =IF(B42,B42-$C$4," ") | E42: =IF(B42,INT(D42)," ") | F42: =IF(B42,((D42-E42)/60*100)," ") | G42: =IF(B42,C42*COS(PI()/180*(E42+F42))," ") | H42: =IF(B42,(C42*SIN(PI()/180*(E42+F42)))," ") | K42: =IF(B42,SUM(G42,-$I$12)," ") | L42: =IF(B42,SUM(H42,-$J$12)," ") | M42: =IF(B42,POWER(K42,2)," ") | N42: =IF(B42,POWER(L42,2)," ")
A43: 6 | D43: =IF(B43,B43-$C$4," ") | E43: =IF(B43,INT(D43)," ") | F43: =IF(B43,((D43-E43)/60*100)," ") | G43: =IF(B43,C43*COS(PI()/180*(E43+F43))," ") | H43: =IF(B43,(C43*SIN(PI()/180*(E43+F43)))," ") | K43: =IF(B43,SUM(G43,-$I$12)," ") | L43: =IF(B43,SUM(H43,-$J$12)," ") | M43: =IF(B43,POWER(K43,2)," ") | N43: =IF(B43,POWER(L43,2)," ")
A44: 7 | D44: =IF(B44,B44-$C$4," ") | E44: =IF(B44,INT(D44)," ") | F44: =IF(B44,((D44-E44)/60*100)," ") | G44: =IF(B44,C44*COS(PI()/180*(E44+F44))," ") | H44: =IF(B44,(C44*SIN(PI()/180*(E44+F44)))," ") | K44: =IF(B44,SUM(G44,-$I$12)," ") | L44: =IF(B44,SUM(H44,-$J$12)," ") | M44: =IF(B44,POWER(K44,2)," ") | N44: =IF(B44,POWER(L44,2)," ")
A45: 8 | D45: =IF(B45,B45-$C$4," ") | E45: =IF(B45,INT(D45)," ") | F45: =IF(B45,((D45-E45)/60*100)," ") | G45: =IF(B45,C45*COS(PI()/180*(E45+F45))," ") | H45: =IF(B45,(C45*SIN(PI()/180*(E45+F45)))," ") | K45: =IF(B45,SUM(G45,-$I$12)," ") | L45: =IF(B45,SUM(H45,-$J$12)," ") | M45: =IF(B45,POWER(K45,2)," ") | N45: =IF(B45,POWER(L45,2)," ")
A46: 9 | D46: =IF(B46,B46-$C$4," ") | E46: =IF(B46,INT(D46)," ") | F46: =IF(B46,((D46-E46)/60*100)," ") | G46: =IF(B46,C46*COS(PI()/180*(E46+F46))," ") | H46: =IF(B46,(C46*SIN(PI()/180*(E46+F46)))," ") | K46: =IF(B46,SUM(G46,-$I$12)," ") | L46: =IF(B46,SUM(H46,-$J$12)," ") | M46: =IF(B46,POWER(K46,2)," ") | N46: =IF(B46,POWER(L46,2)," ")
A47: 10 | D47: =IF(B47,B47-$C$4," ") | E47: =IF(B47,INT(D47)," ") | F47: =IF(B47,((D47-E47)/60*100)," ") | G47: =IF(B47,C47*COS(PI()/180*(E47+F47))," ") | H47: =IF(B47,(C47*SIN(PI()/180*(E47+F47)))," ") | K47: =IF(B47,SUM(G47,-$I$12)," ") | L47: =IF(B47,SUM(H47,-$J$12)," ") | M47: =IF(B47,POWER(K47,2)," ") | N47: =IF(B47,POWER(L47,2)," ")
A48: 11 | D48: =IF(B48,B48-$C$4," ") | E48: =IF(B48,INT(D48)," ") | F48: =IF(B48,((D48-E48)/60*100)," ") | G48: =IF(B48,C48*COS(PI()/180*(E48+F48))," ") | H48: =IF(B48,(C48*SIN(PI()/180*(E48+F48)))," ") | K48: =IF(B48,SUM(G48,-$I$12)," ") | L48: =IF(B48,SUM(H48,-$J$12)," ") | M48: =IF(B48,POWER(K48,2)," ") | N48: =IF(B48,POWER(L48,2)," ")
A49: 12 | D49: =IF(B49,B49-$C$4," ") | E49: =IF(B49,INT(D49)," ") | F49: =IF(B49,((D49-E49)/60*100)," ") | G49: =IF(B49,C49*COS(PI()/180*(E49+F49))," ") | H49: =IF(B49,(C49*SIN(PI()/180*(E49+F49)))," ") | K49: =IF(B49,SUM(G49,-$I$12)," ") | L49: =IF(B49,SUM(H49,-$J$12)," ") | M49: =IF(B49,POWER(K49,2)," ") | N49: =IF(B49,POWER(L49,2)," ")
A50: 13 | D50: =IF(B50,B50-$C$4," ") | E50: =IF(B50,INT(D50)," ") | F50: =IF(B50,((D50-E50)/60*100)," ") | G50: =IF(B50,C50*COS(PI()/180*(E50+F50))," ") | H50: =IF(B50,(C50*SIN(PI()/180*(E50+F50)))," ") | K50: =IF(B50,SUM(G50,-$I$12)," ") | L50: =IF(B50,SUM(H50,-$J$12)," ") | M50: =IF(B50,POWER(K50,2)," ") | N50: =IF(B50,POWER(L50,2)," ")
... A61: 24 | D61: =IF(B61,B61-$C$4," ") | E61: =IF(B61,INT(D61)," ") | F61: =IF(B61,((D61-E61)/60*100)," ") | G61: =IF(B61,C61*COS(PI()/180*(E61+F61))," ") | H61: =IF(B61,(C61*SIN(PI()/180*(E61+F61)))," ") | K61: =IF(B61,SUM(G61,-$I$12)," ") | L61: =IF(B61,SUM(H61,-$J$12)," ") | M61: =IF(B61,POWER(K61,2)," ") | N61: =IF(B61,POWER(L61,2)," ")

Sheet 240-7__4 ркеты
B1: НОМЕР МИШЕНИ
B2: Канал | C2: курс | D2: Vпр | E2: Нпус | F2: Дпус | I2: Центр рассеивания НАР
B3: ЦУ | D3: км/ч | E3: м | F3: м
B4: НВГЦ/ЛЦУ | C4: 270 | I4: =(I12+I38+I64+I90)/4 -> 81.948793 | J4: =(J12+J38+J64+J90)/4 -> -33.668476
B5: Число КОБЭ | C5: Всего | D5: НАР 1 | E5: НАР 2 | F5: НАР 3 | G5: НАР 4 | I5: x | J5: z
C6: =D6+F6+E6+G6 -> 76 | D6: 22 | E6: 16 | F6: 16 | G6: 22
A10: КОБЭ от НАР 1
A11: номер п/п | B11: азимут | C11: дальность | D11: Азимут за вычетом боевого курса | E11: градусы | F11: минуты (в сотых градуса) | G11: х | H11: z | I11: Мх | J11: Мz | K11: Хт-Мх | L11: Zт-Мz | M11: (Хт-Мх)*2 | N11: (Zт-Мz)*2 | O11: N-1 | P11: Σ(Хт-Мх)*2 | Q11: Σ(Zт-Мz)*2 | R11: (Σ(Хт-Мх)*2)/(N-1) | S11: (Σ(Zт-Мz)*2)/(N-1) | T11: Сигма X | U11: Сигма Z | V11: σX*σZ | W11: СКО КОБЭ
A12: 1 | B12: 262.3 | C12: 120 | D12: =IF(B12,B12-$C$4," ") -> -7.7 | E12: =IF(B12,INT(D12)," ") -> -8 | F12: =IF(B12,((D12-E12)/60*100)," ") -> 0.5 | G12: =IF(B12,C12*COS(PI()/180*(E12+F12))," ") -> 118.97338 | H12: =IF(B12,(C12*SIN(PI()/180*(E12+F12)))," ") -> -15.663143 | I12: =SUM(G12:G35)/D6 -> 116.14276 | J12: =SUM(H12:H35)/D6 -> 19.205126 | K12: =IF(B12,SUM(G12,-$I$12)," ") -> 2.8306197 | L12: =IF(B12,SUM(H12,-$J$12)," ") -> -34.868269 | M12: =IF(B12,POWER(K12,2)," ") -> 8.0124078 | N12: =IF(B12,POWER(L12,2)," ") -> 1215.7962 | O12: =D6-1 -> 21 | P12: =SUM(M12:M35) -> 6912.2007 | Q12: =SUM(N12:N35) -> 8552.2741 | R12: =PRODUCT(P12,1/$O$12) -> 329.15241 | S12: =PRODUCT(Q12,1/$O$12) -> 407.25115 | T12: =SQRT(R12) -> 18.142558 | U12: =SQRT(S12) -> 20.180465 | V12: =PRODUCT(T12:U12) -> 366.12525 | W12: =SQRT(V12) -> 19.1344
A13: 2 | B13: 269.3 | C13: 160 | D13: =IF(B13,B13-$C$4," ") -> -0.7 | E13: =IF(B13,INT(D13)," ") -> -1 | F13: =IF(B13,((D13-E13)/60*100)," ") -> 0.5 | G13: =IF(B13,C13*COS(PI()/180*(E13+F13))," ") -> 159.99391 | H13: =IF(B13,(C13*SIN(PI()/180*(E13+F13)))," ") -> -1.3962457 | K13: =IF(B13,SUM(G13,-$I$12)," ") -> 43.851144 | L13: =IF(B13,SUM(H13,-$J$12)," ") -> -20.601372 | M13: =IF(B13,POWER(K13,2)," ") -> 1922.9228 | N13: =IF(B13,POWER(L13,2)," ") -> 424.41651 | AA13: 262.3 | AB13: 120
A14: 3 | B14: 289.05 | C14: 106 | D14: =IF(B14,B14-$C$4," ") -> 19.05 | E14: =IF(B14,INT(D14)," ") -> 19 | F14: =IF(B14,((D14-E14)/60*100)," ") -> 0.083333333 | G14: =IF(B14,C14*COS(PI()/180*(E14+F14))," ") -> 100.17467 | H14: =IF(B14,(C14*SIN(PI()/180*(E14+F14)))," ") -> 34.655959 | K14: =IF(B14,SUM(G14,-$I$12)," ") -> -15.968094 | L14: =IF(B14,SUM(H14,-$J$12)," ") -> 15.450833 | M14: =IF(B14,POWER(K14,2)," ") -> 254.98002 | N14: =IF(B14,POWER(L14,2)," ") -> 238.72825 | AA14: 269.3 | AB14: 160
A15: 4 | B15: 279.4 | C15: 102 | D15: =IF(B15,B15-$C$4," ") -> 9.4 | E15: =IF(B15,INT(D15)," ") -> 9 | F15: =IF(B15,((D15-E15)/60*100)," ") -> 0.66666667 | G15: =IF(B15,C15*COS(PI()/180*(E15+F15))," ") -> 100.55174 | H15: =IF(B15,(C15*SIN(PI()/180*(E15+F15)))," ") -> 17.127421 | K15: =IF(B15,SUM(G15,-$I$12)," ") -> -15.591028 | L15: =IF(B15,SUM(H15,-$J$12)," ") -> -2.077705 | M15: =IF(B15,POWER(K15,2)," ") -> 243.08017 | N15: =IF(B15,POWER(L15,2)," ") -> 4.3168579
A16: 5 | B16: 285.2 | C16: 106 | D16: =IF(B16,B16-$C$4," ") -> 15.2 | E16: =IF(B16,INT(D16)," ") -> 15 | F16: =IF(B16,((D16-E16)/60*100)," ") -> 0.33333333 | G16: =IF(B16,C16*COS(PI()/180*(E16+F16))," ") -> 102.2268 | H16: =IF(B16,(C16*SIN(PI()/180*(E16+F16)))," ") -> 28.030021 | K16: =IF(B16,SUM(G16,-$I$12)," ") -> -13.915967 | L16: =IF(B16,SUM(H16,-$J$12)," ") -> 8.8248952 | M16: =IF(B16,POWER(K16,2)," ") -> 193.65414 | N16: =IF(B16,POWER(L16,2)," ") -> 77.878776
A17: 6 | B17: 273.05 | C17: 104 | D17: =IF(B17,B17-$C$4," ") -> 3.05 | E17: =IF(B17,INT(D17)," ") -> 3 | F17: =IF(B17,((D17-E17)/60*100)," ") -> 0.083333333 | G17: =IF(B17,C17*COS(PI()/180*(E17+F17))," ") -> 103.84945 | H17: =IF(B17,(C17*SIN(PI()/180*(E17+F17)))," ") -> 5.5939882 | K17: =IF(B17,SUM(G17,-$I$12)," ") -> -12.293318 | L17: =IF(B17,SUM(H17,-$J$12)," ") -> -13.611138 | M17: =IF(B17,POWER(K17,2)," ") -> 151.12568 | N17: =IF(B17,POWER(L17,2)," ") -> 185.26307
A18: 7 | B18: 275.2 | C18: 106 | D18: =IF(B18,B18-$C$4," ") -> 5.2 | E18: =IF(B18,INT(D18)," ") -> 5 | F18: =IF(B18,((D18-E18)/60*100)," ") -> 0.33333333 | G18: =IF(B18,C18*COS(PI()/180*(E18+F18))," ") -> 105.5411 | H18: =IF(B18,(C18*SIN(PI()/180*(E18+F18)))," ") -> 9.8526853 | K18: =IF(B18,SUM(G18,-$I$12)," ") -> -10.60166 | L18: =IF(B18,SUM(H18,-$J$12)," ") -> -9.3524407 | M18: =IF(B18,POWER(K18,2)," ") -> 112.39519 | N18: =IF(B18,POWER(L18,2)," ") -> 87.468147
A19: 8 | B19: 264.45 | C19: 106 | D19: =IF(B19,B19-$C$4," ") -> -5.55 | E19: =IF(B19,INT(D19)," ") -> -6 | F19: =IF(B19,((D19-E19)/60*100)," ") -> 0.75 | G19: =IF(B19,C19*COS(PI()/180*(E19+F19))," ") -> 105.55532 | H19: =IF(B19,(C19*SIN(PI()/180*(E19+F19)))," ") -> -9.6991716 | K19: =IF(B19,SUM(G19,-$I$12)," ") -> -10.587441 | L19: =IF(B19,SUM(H19,-$J$12)," ") -> -28.904298 | M19: =IF(B19,POWER(K19,2)," ") -> 112.09391 | N19: =IF(B19,POWER(L19,2)," ") -> 835.45842
A20: 9 | B20: 275.35 | C20: 108 | D20: =IF(B20,B20-$C$4," ") -> 5.35 | E20: =IF(B20,INT(D20)," ") -> 5 | F20: =IF(B20,((D20-E20)/60*100)," ") -> 0.58333333 | G20: =IF(B20,C20*COS(PI()/180*(E20+F20))," ") -> 107.48762 | H20: =IF(B20,(C20*SIN(PI()/180*(E20+F20)))," ") -> 10.507687 | K20: =IF(B20,SUM(G20,-$I$12)," ") -> -8.6551434 | L20: =IF(B20,SUM(H20,-$J$12)," ") -> -8.6974392 | M20: =IF(B20,POWER(K20,2)," ") -> 74.911507 | N20: =IF(B20,POWER(L20,2)," ") -> 75.645449
A21: 10 | B21: 279.45 | C21: 116 | D21: =IF(B21,B21-$C$4," ") -> 9.45 | E21: =IF(B21,INT(D21)," ") -> 9 | F21: =IF(B21,((D21-E21)/60*100)," ") -> 0.75 | G21: =IF(B21,C21*COS(PI()/180*(E21+F21))," ") -> 114.3245 | H21: =IF(B21,(C21*SIN(PI()/180*(E21+F21)))," ") -> 19.644542 | K21: =IF(B21,SUM(G21,-$I$12)," ") -> -1.8182608 | L21: =IF(B21,SUM(H21,-$J$12)," ") -> 0.4394165 | M21: =IF(B21,POWER(K21,2)," ") -> 3.3060724 | N21: =IF(B21,POWER(L21,2)," ") -> 0.19308686
A22: 11 | B22: 279.1 | C22: 116 | D22: =IF(B22,B22-$C$4," ") -> 9.1 | E22: =IF(B22,INT(D22)," ") -> 9 | F22: =IF(B22,((D22-E22)/60*100)," ") -> 0.16666667 | G22: =IF(B22,C22*COS(PI()/180*(E22+F22))," ") -> 114.51858 | H22: =IF(B22,(C22*SIN(PI()/180*(E22+F22)))," ") -> 18.479597 | K22: =IF(B22,SUM(G22,-$I$12)," ") -> -1.6241866 | L22: =IF(B22,SUM(H22,-$J$12)," ") -> -0.72552925 | M22: =IF(B22,POWER(K22,2)," ") -> 2.637982 | N22: =IF(B22,POWER(L22,2)," ") -> 0.52639269
A23: 12 | B23: 282.05 | C23: 128 | D23: =IF(B23,B23-$C$4," ") -> 12.05 | E23: =IF(B23,INT(D23)," ") -> 12 | F23: =IF(B23,((D23-E23)/60*100)," ") -> 0.083333333 | G23: =IF(B23,C23*COS(PI()/180*(E23+F23))," ") -> 125.16405 | H23: =IF(B23,(C23*SIN(PI()/180*(E23+F23)))," ") -> 26.794768 | K23: =IF(B23,SUM(G23,-$I$12)," ") -> 9.0212902 | L23: =IF(B23,SUM(H23,-$J$12)," ") -> 7.5896425 | M23: =IF(B23,POWER(K23,2)," ") -> 81.383677 | N23: =IF(B23,POWER(L23,2)," ") -> 57.602673
A24: 13 | B24: 279.45 | C24: 128 | D24: =IF(B24,B24-$C$4," ") -> 9.45 | E24: =IF(B24,INT(D24)," ") -> 9 | F24: =IF(B24,((D24-E24)/60*100)," ") -> 0.75 | G24: =IF(B24,C24*COS(PI()/180*(E24+F24))," ") -> 126.15118 | H24: =IF(B24,(C24*SIN(PI()/180*(E24+F24)))," ") -> 21.676736 | K24: =IF(B24,SUM(G24,-$I$12)," ") -> 10.008412 | L24: =IF(B24,SUM(H24,-$J$12)," ") -> 2.4716105 | M24: =IF(B24,POWER(K24,2)," ") -> 100.16831 | N24: =IF(B24,POWER(L24,2)," ") -> 6.1088587
A25: 14 | B25: 278.55 | C25: 132 | D25: =IF(B25,B25-$C$4," ") -> 8.55 | E25: =IF(B25,INT(D25)," ") -> 8 | F25: =IF(B25,((D25-E25)/60*100)," ") -> 0.91666667 | G25: =IF(B25,C25*COS(PI()/180*(E25+F25))," ") -> 130.40476 | H25: =IF(B25,(C25*SIN(PI()/180*(E25+F25)))," ") -> 20.459705 | K25: =IF(B25,SUM(G25,-$I$12)," ") -> 14.261993 | L25: =IF(B25,SUM(H25,-$J$12)," ") -> 1.2545791 | M25: =IF(B25,POWER(K25,2)," ") -> 203.40443 | N25: =IF(B25,POWER(L25,2)," ") -> 1.5739688
A26: 15 | B26: 280.3 | C26: 134 | D26: =IF(B26,B26-$C$4," ") -> 10.3 | E26: =IF(B26,INT(D26)," ") -> 10 | F26: =IF(B26,((D26-E26)/60*100)," ") -> 0.5 | G26: =IF(B26,C26*COS(PI()/180*(E26+F26))," ") -> 131.75616 | H26: =IF(B26,(C26*SIN(PI()/180*(E26+F26)))," ") -> 24.41956 | K26: =IF(B26,SUM(G26,-$I$12)," ") -> 15.613394 | L26: =IF(B26,SUM(H26,-$J$12)," ") -> 5.2144345 | M26: =IF(B26,POWER(K26,2)," ") -> 243.77807 | N26: =IF(B26,POWER(L26,2)," ") -> 27.190327
... A33: 22 | B33: 306 | C33: 132 | D33: =IF(B33,B33-$C$4," ") -> 36 | E33: =IF(B33,INT(D33)," ") -> 36 | F33: =IF(B33,((D33-E33)/60*100)," ") -> 0 | G33: =IF(B33,C33*COS(PI()/180*(E33+F33))," ") -> 106.79024 | H33: =IF(B33,(C33*SIN(PI()/180*(E33+F33)))," ") -> 77.587653 | K33: =IF(B33,SUM(G33,-$I$12)," ") -> -9.3525204 | L33: =IF(B33,SUM(H33,-$J$12)," ") -> 58.382527 | M33: =IF(B33,POWER(K33,2)," ") -> 87.469638 | N33: =IF(B33,POWER(L33,2)," ") -> 3408.5195
A34: 23 | D34: =IF(B34,B34-$C$4," ") | E34: =IF(B34,INT(D34)," ") | F34: =IF(B34,((D34-E34)/60*100)," ") | G34: =IF(B34,C34*COS(PI()/180*(E34+F34))," ") | H34: =IF(B34,(C34*SIN(PI()/180*(E34+F34)))," ") | K34: =IF(B34,SUM(G34,-$I$12)," ") | L34: =IF(B34,SUM(H34,-$J$12)," ") | M34: =IF(B34,POWER(K34,2)," ") | N34: =IF(B34,POWER(L34,2)," ")
A35: 24 | D35: =IF(B35,B35-$C$4," ") | E35: =IF(B35,INT(D35)," ") | F35: =IF(B35,((D35-E35)/60*100)," ") | G35: =IF(B35,C35*COS(PI()/180*(E35+F35))," ") | H35: =IF(B35,(C35*SIN(PI()/180*(E35+F35)))," ") | K35: =IF(B35,SUM(G35,-$I$12)," ") | L35: =IF(B35,SUM(H35,-$J$12)," ") | M35: =IF(B35,POWER(K35,2)," ") | N35: =IF(B35,POWER(L35,2)," ")
A36: КОБЭ от НАР 2
A37: номер п/п | B37: азимут | C37: дальность | D37: Азимут за вычетом боевого курса | E37: градусы | F37: минуты (в сотых градуса) | G37: х | H37: z | I37: Мх | J37: Мz | K37: Хт-Мх | L37: Zт-Мz | M37: (Хт-Мх)*2 | N37: (Zт-Мz)*2 | O37: N-1 | P37: Σ(Хт-Мх)*2 | Q37: Σ(Zт-Мz)*2 | R37: (Σ(Хт-Мх)*2)/(N-1) | S37: (Σ(Zт-Мz)*2)/(N-1) | T37: Сигма X | U37: Сигма Z | V37: σX*σZ | W37: СКО КОБЭ
A38: 1 | B38: 248.2 | C38: 20 | D38: =IF(B38,B38-$C$4," ") -> -21.8 | E38: =IF(B38,INT(D38)," ") -> -22 | F38: =IF(B38,((D38-E38)/60*100)," ") -> 0.33333333 | G38: =IF(B38,C38*COS(PI()/180*(E38+F38))," ") -> 18.58695 | H38: =IF(B38,(C38*SIN(PI()/180*(E38+F38)))," ") -> -7.3841229 | I38: =SUM(G38:G61)/E6 -> 67.287428 | J38: =SUM(H38:H61)/E6 -> 18.996543 | K38: =IF(B38,SUM(G38,-$I$12)," ") -> -97.555813 | L38: =IF(B38,SUM(H38,-$J$12)," ") -> -26.589249 | M38: =IF(B38,POWER(K38,2)," ") -> 9517.1367 | N38: =IF(B38,POWER(L38,2)," ") -> 706.98816 | O38: =E6-1 -> 15 | P38: =SUM(M38:M61) -> 43820.745 | Q38: =SUM(N38:N61) -> 5681.987 | R38: =PRODUCT(P38,1/$O$38) -> 2921.383 | S38: =PRODUCT(Q38,1/$O$38) -> 378.79913 | T38: =SQRT(R38) -> 54.04982 | U38: =SQRT(S38) -> 19.462763 | V38: =PRODUCT(T38:U38) -> 1051.9588 | W38: =SQRT(V38) -> 32.433915
A39: 2 | B39: 283.2 | C39: 40 | D39: =IF(B39,B39-$C$4," ") -> 13.2 | E39: =IF(B39,INT(D39)," ") -> 13 | F39: =IF(B39,((D39-E39)/60*100)," ") -> 0.33333333 | G39: =IF(B39,C39*COS(PI()/180*(E39+F39))," ") -> 38.921795 | H39: =IF(B39,(C39*SIN(PI()/180*(E39+F39)))," ") -> 9.2246348 | K39: =IF(B39,SUM(G39,-$I$12)," ") -> -77.220969 | L39: =IF(B39,SUM(H39,-$J$12)," ") -> -9.9804911 | M39: =IF(B39,POWER(K39,2)," ") -> 5963.078 | N39: =IF(B39,POWER(L39,2)," ") -> 99.610203
A40: 3 | B40: 293.4 | C40: 56 | D40: =IF(B40,B40-$C$4," ") -> 23.4 | E40: =IF(B40,INT(D40)," ") -> 23 | F40: =IF(B40,((D40-E40)/60*100)," ") -> 0.66666667 | G40: =IF(B40,C40*COS(PI()/180*(E40+F40))," ") -> 51.290192 | H40: =IF(B40,(C40*SIN(PI()/180*(E40+F40)))," ") -> 22.47924 | K40: =IF(B40,SUM(G40,-$I$12)," ") -> -64.852572 | L40: =IF(B40,SUM(H40,-$J$12)," ") -> 3.2741139 | M40: =IF(B40,POWER(K40,2)," ") -> 4205.8561 | N40: =IF(B40,POWER(L40,2)," ") -> 10.719822
A41: 4 | B41: 291.4 | C41: 60 | D41: =IF(B41,B41-$C$4," ") -> 21.4 | E41: =IF(B41,INT(D41)," ") -> 21 | F41: =IF(B41,((D41-E41)/60*100)," ") -> 0.66666667 | G41: =IF(B41,C41*COS(PI()/180*(E41+F41))," ") -> 55.760851 | H41: =IF(B41,(C41*SIN(PI()/180*(E41+F41)))," ") -> 22.152369 | K41: =IF(B41,SUM(G41,-$I$12)," ") -> -60.381912 | L41: =IF(B41,SUM(H41,-$J$12)," ") -> 2.9472429 | M41: =IF(B41,POWER(K41,2)," ") -> 3645.9753 | N41: =IF(B41,POWER(L41,2)," ") -> 8.6862407
A42: 5 | B42: 270.2 | C42: 58 | D42: =IF(B42,B42-$C$4," ") -> 0.2 | E42: =IF(B42,INT(D42)," ") -> 0 | F42: =IF(B42,((D42-E42)/60*100)," ") -> 0.33333333 | G42: =IF(B42,C42*COS(PI()/180*(E42+F42))," ") -> 57.999018 | H42: =IF(B42,(C42*SIN(PI()/180*(E42+F42)))," ") -> 0.33742842 | K42: =IF(B42,SUM(G42,-$I$12)," ") -> -58.143745 | L42: =IF(B42,SUM(H42,-$J$12)," ") -> -18.867698 | M42: =IF(B42,POWER(K42,2)," ") -> 3380.6951 | N42: =IF(B42,POWER(L42,2)," ") -> 355.99001
A43: 6 | B43: 278.05 | C43: 66 | D43: =IF(B43,B43-$C$4," ") -> 8.05 | E43: =IF(B43,INT(D43)," ") -> 8 | F43: =IF(B43,((D43-E43)/60*100)," ") -> 0.083333333 | G43: =IF(B43,C43*COS(PI()/180*(E43+F43))," ") -> 65.344264 | H43: =IF(B43,(C43*SIN(PI()/180*(E43+F43)))," ") -> 9.2804738 | K43: =IF(B43,SUM(G43,-$I$12)," ") -> -50.7985 | L43: =IF(B43,SUM(H43,-$J$12)," ") -> -9.9246521 | M43: =IF(B43,POWER(K43,2)," ") -> 2580.4876 | N43: =IF(B43,POWER(L43,2)," ") -> 98.49872
A44: 7 | B44: 271.25 | C44: 68 | D44: =IF(B44,B44-$C$4," ") -> 1.25 | E44: =IF(B44,INT(D44)," ") -> 1 | F44: =IF(B44,((D44-E44)/60*100)," ") -> 0.41666667 | G44: =IF(B44,C44*COS(PI()/180*(E44+F44))," ") -> 67.979215 | H44: =IF(B44,(C44*SIN(PI()/180*(E44+F44)))," ") -> 1.6811625 | K44: =IF(B44,SUM(G44,-$I$12)," ") -> -48.163549 | L44: =IF(B44,SUM(H44,-$J$12)," ") -> -17.523963 | M44: =IF(B44,POWER(K44,2)," ") -> 2319.7274 | N44: =IF(B44,POWER(L44,2)," ") -> 307.08929
A45: 8 | B45: 289.15 | C45: 74 | D45: =IF(B45,B45-$C$4," ") -> 19.15 | E45: =IF(B45,INT(D45)," ") -> 19 | F45: =IF(B45,((D45-E45)/60*100)," ") -> 0.25 | G45: =IF(B45,C45*COS(PI()/180*(E45+F45))," ") -> 69.862588 | H45: =IF(B45,(C45*SIN(PI()/180*(E45+F45)))," ") -> 24.397108 | K45: =IF(B45,SUM(G45,-$I$12)," ") -> -46.280176 | L45: =IF(B45,SUM(H45,-$J$12)," ") -> 5.1919818 | M45: =IF(B45,POWER(K45,2)," ") -> 2141.8547 | N45: =IF(B45,POWER(L45,2)," ") -> 26.956675
A46: 9 | B46: 276.25 | C46: 74 | D46: =IF(B46,B46-$C$4," ") -> 6.25 | E46: =IF(B46,INT(D46)," ") -> 6 | F46: =IF(B46,((D46-E46)/60*100)," ") -> 0.41666667 | G46: =IF(B46,C46*COS(PI()/180*(E46+F46))," ") -> 73.536423 | H46: =IF(B46,(C46*SIN(PI()/180*(E46+F46)))," ") -> 8.2700922 | K46: =IF(B46,SUM(G46,-$I$12)," ") -> -42.60634 | L46: =IF(B46,SUM(H46,-$J$12)," ") -> -10.935034 | M46: =IF(B46,POWER(K46,2)," ") -> 1815.3002 | N46: =IF(B46,POWER(L46,2)," ") -> 119.57496
A47: 10 | B47: 306.4 | C47: 92 | D47: =IF(B47,B47-$C$4," ") -> 36.4 | E47: =IF(B47,INT(D47)," ") -> 36 | F47: =IF(B47,((D47-E47)/60*100)," ") -> 0.66666667 | G47: =IF(B47,C47*COS(PI()/180*(E47+F47))," ") -> 73.795334 | H47: =IF(B47,(C47*SIN(PI()/180*(E47+F47)))," ") -> 54.93859 | K47: =IF(B47,SUM(G47,-$I$12)," ") -> -42.34743 | L47: =IF(B47,SUM(H47,-$J$12)," ") -> 35.733464 | M47: =IF(B47,POWER(K47,2)," ") -> 1793.3048 | N47: =IF(B47,POWER(L47,2)," ") -> 1276.8805
A48: 11 | B48: 311.15 | C48: 102 | D48: =IF(B48,B48-$C$4," ") -> 41.15 | E48: =IF(B48,INT(D48)," ") -> 41 | F48: =IF(B48,((D48-E48)/60*100)," ") -> 0.25 | G48: =IF(B48,C48*COS(PI()/180*(E48+F48))," ") -> 76.68766 | H48: =IF(B48,(C48*SIN(PI()/180*(E48+F48)))," ") -> 67.253273 | K48: =IF(B48,SUM(G48,-$I$12)," ") -> -39.455103 | L48: =IF(B48,SUM(H48,-$J$12)," ") -> 48.048147 | M48: =IF(B48,POWER(K48,2)," ") -> 1556.7052 | N48: =IF(B48,POWER(L48,2)," ") -> 2308.6244
A49: 12 | B49: 283.45 | C49: 84 | D49: =IF(B49,B49-$C$4," ") -> 13.45 | E49: =IF(B49,INT(D49)," ") -> 13 | F49: =IF(B49,((D49-E49)/60*100)," ") -> 0.75 | G49: =IF(B49,C49*COS(PI()/180*(E49+F49))," ") -> 81.592734 | H49: =IF(B49,(C49*SIN(PI()/180*(E49+F49)))," ") -> 19.965615 | K49: =IF(B49,SUM(G49,-$I$12)," ") -> -34.55003 | L49: =IF(B49,SUM(H49,-$J$12)," ") -> 0.76048901 | M49: =IF(B49,POWER(K49,2)," ") -> 1193.7046 | N49: =IF(B49,POWER(L49,2)," ") -> 0.57834354
...

Sheet 240-8
B1: 240-8
B2: Канал | C2: курс | D2: Vпр | E2: Нпус | F2: Дпус | I2: Центр рассеивания НАР
B3: ЦУ | D3: км/ч | E3: м | F3: м
B4: НВГЦ/ЛЦУ | C4: 270 | I4: =IF(E6,((I12+I38)/2),I12) -> 144.1354 | J4: =IF(E6,((J12+J38)/2),J12) -> -28.705682
B5: Число КОБЭ | C5: Всего | D5: НАР 1 | E5: НАР 2 | I5: x | J5: z
C6: 23 | D6: 23 | E6: 0
A10: КОБЭ от НАР 1
A11: номер п/п | B11: азимут | C11: дальность | D11: Азимут за вычетом боевого курса | E11: градусы | F11: минуты (в сотых градуса) | G11: х | H11: z | I11: Мх | J11: Мz | K11: Хт-Мх | L11: Zт-Мz | M11: (Хт-Мх)*2 | N11: (Zт-Мz)*2 | O11: N-1 | P11: Σ(Хт-Мх)*2 | Q11: Σ(Zт-Мz)*2 | R11: (Σ(Хт-Мх)*2)/(N-1) | S11: (Σ(Zт-Мz)*2)/(N-1) | T11: Сигма X | U11: Сигма Z | V11: σX*σZ | W11: СКО КОБЭ
A12: 1 | B12: 255.55 | C12: 80 | D12: =IF(B12,B12-$C$4," ") -> -14.45 | E12: =IF(B12,INT(D12)," ") -> -15 | F12: =IF(B12,((D12-E12)/60*100)," ") -> 0.91666667 | G12: =IF(B12,C12*COS(PI()/180*(E12+F12))," ") -> 77.595427 | H12: =IF(B12,(C12*SIN(PI()/180*(E12+F12)))," ") -> -19.46663 | I12: =SUM(G12:G34)/D6 -> 144.1354 | J12: =SUM(H12:H34)/D6 -> -28.705682 | K12: =IF(B12,SUM(G12,-$I$12)," ") -> -66.53997 | L12: =IF(B12,SUM(H12,-$J$12)," ") -> 9.2390519 | M12: =IF(B12,POWER(K12,2)," ") -> 4427.5675 | N12: =IF(B12,POWER(L12,2)," ") -> 85.360079 | O12: =D6-1 -> 22 | P12: =SUM(M12:M35) -> 27592.728 | Q12: =SUM(N12:N35) -> 1122.6105 | R12: =PRODUCT(P12,1/$O$12) -> 1254.2149 | S12: =PRODUCT(Q12,1/$O$12) -> 51.027748 | T12: =SQRT(R12) -> 35.414897 | U12: =SQRT(S12) -> 7.1433709 | V12: =PRODUCT(T12:U12) -> 252.98174 | W12: =SQRT(V12) -> 15.9054
A13: 2 | B13: 256.35 | C13: 90 | D13: =IF(B13,B13-$C$4," ") -> -13.65 | E13: =IF(B13,INT(D13)," ") -> -14 | F13: =IF(B13,((D13-E13)/60*100)," ") -> 0.58333333 | G13: =IF(B13,C13*COS(PI()/180*(E13+F13))," ") -> 87.543758 | H13: =IF(B13,(C13*SIN(PI()/180*(E13+F13)))," ") -> -20.882778 | K13: =IF(B13,SUM(G13,-$I$12)," ") -> -56.591638 | L13: =IF(B13,SUM(H13,-$J$12)," ") -> 7.8229044 | M13: =IF(B13,POWER(K13,2)," ") -> 3202.6135 | N13: =IF(B13,POWER(L13,2)," ") -> 61.197833
A14: 3 | B14: 256.55 | C14: 120 | D14: =IF(B14,B14-$C$4," ") -> -13.45 | E14: =IF(B14,INT(D14)," ") -> -14 | F14: =IF(B14,((D14-E14)/60*100)," ") -> 0.91666667 | G14: =IF(B14,C14*COS(PI()/180*(E14+F14))," ") -> 116.88502 | H14: =IF(B14,(C14*SIN(PI()/180*(E14+F14)))," ") -> -27.164158 | K14: =IF(B14,SUM(G14,-$I$12)," ") -> -27.250374 | L14: =IF(B14,SUM(H14,-$J$12)," ") -> 1.5415245 | M14: =IF(B14,POWER(K14,2)," ") -> 742.58288 | N14: =IF(B14,POWER(L14,2)," ") -> 2.3762977
A15: 4 | B15: 257.05 | C15: 126 | D15: =IF(B15,B15-$C$4," ") -> -12.95 | E15: =IF(B15,INT(D15)," ") -> -13 | F15: =IF(B15,((D15-E15)/60*100)," ") -> 0.083333333 | G15: =IF(B15,C15*COS(PI()/180*(E15+F15))," ") -> 122.81172 | H15: =IF(B15,(C15*SIN(PI()/180*(E15+F15)))," ") -> -28.16524 | K15: =IF(B15,SUM(G15,-$I$12)," ") -> -21.323674 | L15: =IF(B15,SUM(H15,-$J$12)," ") -> 0.54044174 | M15: =IF(B15,POWER(K15,2)," ") -> 454.69907 | N15: =IF(B15,POWER(L15,2)," ") -> 0.29207728
A16: 5 | B16: 256.1 | C16: 130 | D16: =IF(B16,B16-$C$4," ") -> -13.9 | E16: =IF(B16,INT(D16)," ") -> -14 | F16: =IF(B16,((D16-E16)/60*100)," ") -> 0.16666667 | G16: =IF(B16,C16*COS(PI()/180*(E16+F16))," ") -> 126.22939 | H16: =IF(B16,(C16*SIN(PI()/180*(E16+F16)))," ") -> -31.082792 | K16: =IF(B16,SUM(G16,-$I$12)," ") -> -17.906002 | L16: =IF(B16,SUM(H16,-$J$12)," ") -> -2.37711 | M16: =IF(B16,POWER(K16,2)," ") -> 320.62491 | N16: =IF(B16,POWER(L16,2)," ") -> 5.6506519
A17: 6 | B17: 259 | C17: 132 | D17: =IF(B17,B17-$C$4," ") -> -11 | E17: =IF(B17,INT(D17)," ") -> -11 | F17: =IF(B17,((D17-E17)/60*100)," ") -> 0 | G17: =IF(B17,C17*COS(PI()/180*(E17+F17))," ") -> 129.57479 | H17: =IF(B17,(C17*SIN(PI()/180*(E17+F17)))," ") -> -25.186787 | K17: =IF(B17,SUM(G17,-$I$12)," ") -> -14.560608 | L17: =IF(B17,SUM(H17,-$J$12)," ") -> 3.5188946 | M17: =IF(B17,POWER(K17,2)," ") -> 212.01132 | N17: =IF(B17,POWER(L17,2)," ") -> 12.38262
A18: 7 | B18: 261.35 | C18: 138 | D18: =IF(B18,B18-$C$4," ") -> -8.65 | E18: =IF(B18,INT(D18)," ") -> -9 | F18: =IF(B18,((D18-E18)/60*100)," ") -> 0.58333333 | G18: =IF(B18,C18*COS(PI()/180*(E18+F18))," ") -> 136.51371 | H18: =IF(B18,(C18*SIN(PI()/180*(E18+F18)))," ") -> -20.199169 | K18: =IF(B18,SUM(G18,-$I$12)," ") -> -7.6216847 | L18: =IF(B18,SUM(H18,-$J$12)," ") -> 8.506513 | M18: =IF(B18,POWER(K18,2)," ") -> 58.090077 | N18: =IF(B18,POWER(L18,2)," ") -> 72.360764
A19: 8 | B19: 255.55 | C19: 146 | D19: =IF(B19,B19-$C$4," ") -> -14.45 | E19: =IF(B19,INT(D19)," ") -> -15 | F19: =IF(B19,((D19-E19)/60*100)," ") -> 0.91666667 | G19: =IF(B19,C19*COS(PI()/180*(E19+F19))," ") -> 141.61165 | H19: =IF(B19,(C19*SIN(PI()/180*(E19+F19)))," ") -> -35.5266 | K19: =IF(B19,SUM(G19,-$I$12)," ") -> -2.5237422 | L19: =IF(B19,SUM(H19,-$J$12)," ") -> -6.820918 | M19: =IF(B19,POWER(K19,2)," ") -> 6.3692746 | N19: =IF(B19,POWER(L19,2)," ") -> 46.524923
A20: 9 | B20: 262.05 | C20: 160 | D20: =IF(B20,B20-$C$4," ") -> -7.95 | E20: =IF(B20,INT(D20)," ") -> -8 | F20: =IF(B20,((D20-E20)/60*100)," ") -> 0.083333333 | G20: =IF(B20,C20*COS(PI()/180*(E20+F20))," ") -> 158.47511 | H20: =IF(B20,(C20*SIN(PI()/180*(E20+F20)))," ") -> -22.037227 | K20: =IF(B20,SUM(G20,-$I$12)," ") -> 14.339714 | L20: =IF(B20,SUM(H20,-$J$12)," ") -> 6.6684552 | M20: =IF(B20,POWER(K20,2)," ") -> 205.62739 | N20: =IF(B20,POWER(L20,2)," ") -> 44.468295
A21: 10 | B21: 263.05 | C21: 164 | D21: =IF(B21,B21-$C$4," ") -> -6.95 | E21: =IF(B21,INT(D21)," ") -> -7 | F21: =IF(B21,((D21-E21)/60*100)," ") -> 0.083333333 | G21: =IF(B21,C21*COS(PI()/180*(E21+F21))," ") -> 162.80647 | H21: =IF(B21,(C21*SIN(PI()/180*(E21+F21)))," ") -> -19.749801 | K21: =IF(B21,SUM(G21,-$I$12)," ") -> 18.671069 | L21: =IF(B21,SUM(H21,-$J$12)," ") -> 8.9558811 | M21: =IF(B21,POWER(K21,2)," ") -> 348.60883 | N21: =IF(B21,POWER(L21,2)," ") -> 80.207807
A22: 11 | B22: 257.25 | C22: 164 | D22: =IF(B22,B22-$C$4," ") -> -12.75 | E22: =IF(B22,INT(D22)," ") -> -13 | F22: =IF(B22,((D22-E22)/60*100)," ") -> 0.41666667 | G22: =IF(B22,C22*COS(PI()/180*(E22+F22))," ") -> 160.06075 | H22: =IF(B22,(C22*SIN(PI()/180*(E22+F22)))," ") -> -35.728933 | K22: =IF(B22,SUM(G22,-$I$12)," ") -> 15.925352 | L22: =IF(B22,SUM(H22,-$J$12)," ") -> -7.0232513 | M22: =IF(B22,POWER(K22,2)," ") -> 253.61684 | N22: =IF(B22,POWER(L22,2)," ") -> 49.326059
A23: 12 | B23: 259.05 | C23: 166 | D23: =IF(B23,B23-$C$4," ") -> -10.95 | E23: =IF(B23,INT(D23)," ") -> -11 | F23: =IF(B23,((D23-E23)/60*100)," ") -> 0.083333333 | G23: =IF(B23,C23*COS(PI()/180*(E23+F23))," ") -> 162.99601 | H23: =IF(B23,(C23*SIN(PI()/180*(E23+F23)))," ") -> -31.437258 | K23: =IF(B23,SUM(G23,-$I$12)," ") -> 18.860612 | L23: =IF(B23,SUM(H23,-$J$12)," ") -> -2.7315764 | M23: =IF(B23,POWER(K23,2)," ") -> 355.72268 | N23: =IF(B23,POWER(L23,2)," ") -> 7.4615099
A24: 13 | B24: 258.4 | C24: 176 | D24: =IF(B24,B24-$C$4," ") -> -11.6 | E24: =IF(B24,INT(D24)," ") -> -12 | F24: =IF(B24,((D24-E24)/60*100)," ") -> 0.66666667 | G24: =IF(B24,C24*COS(PI()/180*(E24+F24))," ") -> 172.56809 | H24: =IF(B24,(C24*SIN(PI()/180*(E24+F24)))," ") -> -34.586923 | K24: =IF(B24,SUM(G24,-$I$12)," ") -> 28.432691 | L24: =IF(B24,SUM(H24,-$J$12)," ") -> -5.8812412 | M24: =IF(B24,POWER(K24,2)," ") -> 808.41789 | N24: =IF(B24,POWER(L24,2)," ") -> 34.588999
... A34: 23 | B34: 261.15 | C34: 198 | D34: =IF(B34,B34-$C$4," ") -> -8.85 | E34: =IF(B34,INT(D34)," ") -> -9 | F34: =IF(B34,((D34-E34)/60*100)," ") -> 0.25 | G34: =IF(B34,C34*COS(PI()/180*(E34+F34))," ") -> 195.69558 | H34: =IF(B34,(C34*SIN(PI()/180*(E34+F34)))," ") -> -30.12043 | K34: =IF(B34,SUM(G34,-$I$12)," ") -> 51.560182 | L34: =IF(B34,SUM(H34,-$J$12)," ") -> -1.4147484 | M34: =IF(B34,POWER(K34,2)," ") -> 2658.4524 | N34: =IF(B34,POWER(L34,2)," ") -> 2.0015131
A35: 24 | D35: =IF(B35,B35-$C$4," ") | E35: =IF(B35,INT(D35)," ") | F35: =IF(B35,((D35-E35)/60*100)," ") | G35: =IF(B35,C35*COS(PI()/180*(E35+F35))," ") | H35: =IF(B35,(C35*SIN(PI()/180*(E35+F35)))," ") | K35: =IF(B35,SUM(G35,-$I$12)," ") | L35: =IF(B35,SUM(H35,-$J$12)," ") | M35: =IF(B35,POWER(K35,2)," ") | N35: =IF(B35,POWER(L35,2)," ")
A36: КОБЭ от НАР 2
A37: номер п/п | B37: азимут | C37: дальность | D37: Азимут за вычетом боевого курса | E37: градусы | F37: минуты (в сотых градуса) | G37: х | H37: z | I37: Мх | J37: Мz | K37: Хт-Мх | L37: Zт-Мz | M37: (Хт-Мх)*2 | N37: (Zт-Мz)*2 | O37: N-1 | P37: Σ(Хт-Мх)*2 | Q37: Σ(Zт-Мz)*2 | R37: (Σ(Хт-Мх)*2)/(N-1) | S37: (Σ(Zт-Мz)*2)/(N-1) | T37: Сигма X | U37: Сигма Z | V37: σX*σZ | W37: СКО КОБЭ
A38: 1 | D38: =IF(B38,B38-$C$4," ") | E38: =IF(B38,INT(D38)," ") | F38: =IF(B38,((D38-E38)/60*100)," ") | G38: =IF(B38,C38*COS(PI()/180*(E38+F38))," ") | H38: =IF(B38,(C38*SIN(PI()/180*(E38+F38)))," ") | I38: =SUM(G38:G61)/E6 -> #DIV/0! | J38: =SUM(H38:H61)/E6 -> #DIV/0! | K38: =IF(B38,SUM(G38,-$I$12)," ") | L38: =IF(B38,SUM(H38,-$J$12)," ") | M38: =IF(B38,POWER(K38,2)," ") | N38: =IF(B38,POWER(L38,2)," ") | O38: =E6-1 -> -1 | P38: =SUM(M38:M61) -> 0 | Q38: =SUM(N38:N61) -> 0 | R38: =PRODUCT(P38,1/$O$38) -> 0 | S38: =PRODUCT(Q38,1/$O$38) -> 0 | T38: =SQRT(R38) -> 0 | U38: =SQRT(S38) -> 0 | V38: =PRODUCT(T38:U38) -> 0 | W38: =SQRT(V38) -> 0
A39: 2 | D39: =IF(B39,B39-$C$4," ") | E39: =IF(B39,INT(D39)," ") | F39: =IF(B39,((D39-E39)/60*100)," ") | G39: =IF(B39,C39*COS(PI()/180*(E39+F39))," ") | H39: =IF(B39,(C39*SIN(PI()/180*(E39+F39)))," ") | K39: =IF(B39,SUM(G39,-$I$12)," ") | L39: =IF(B39,SUM(H39,-$J$12)," ") | M39: =IF(B39,POWER(K39,2)," ") | N39: =IF(B39,POWER(L39,2)," ")
A40: 3 | D40: =IF(B40,B40-$C$4," ") | E40: =IF(B40,INT(D40)," ") | F40: =IF(B40,((D40-E40)/60*100)," ") | G40: =IF(B40,C40*COS(PI()/180*(E40+F40))," ") | H40: =IF(B40,(C40*SIN(PI()/180*(E40+F40)))," ") | K40: =IF(B40,SUM(G40,-$I$12)," ") | L40: =IF(B40,SUM(H40,-$J$12)," ") | M40: =IF(B40,POWER(K40,2)," ") | N40: =IF(B40,POWER(L40,2)," ")
A41: 4 | D41: =IF(B41,B41-$C$4," ") | E41: =IF(B41,INT(D41)," ") | F41: =IF(B41,((D41-E41)/60*100)," ") | G41: =IF(B41,C41*COS(PI()/180*(E41+F41))," ") | H41: =IF(B41,(C41*SIN(PI()/180*(E41+F41)))," ") | K41: =IF(B41,SUM(G41,-$I$12)," ") | L41: =IF(B41,SUM(H41,-$J$12)," ") | M41: =IF(B41,POWER(K41,2)," ") | N41: =IF(B41,POWER(L41,2)," ")
A42: 5 | D42: =IF(B42,B42-$C$4," ") | E42: =IF(B42,INT(D42)," ") | F42: =IF(B42,((D42-E42)/60*100)," ") | G42: =IF(B42,C42*COS(PI()/180*(E42+F42))," ") | H42: =IF(B42,(C42*SIN(PI()/180*(E42+F42)))," ") | K42: =IF(B42,SUM(G42,-$I$12)," ") | L42: =IF(B42,SUM(H42,-$J$12)," ") | M42: =IF(B42,POWER(K42,2)," ") | N42: =IF(B42,POWER(L42,2)," ")
A43: 6 | D43: =IF(B43,B43-$C$4," ") | E43: =IF(B43,INT(D43)," ") | F43: =IF(B43,((D43-E43)/60*100)," ") | G43: =IF(B43,C43*COS(PI()/180*(E43+F43))," ") | H43: =IF(B43,(C43*SIN(PI()/180*(E43+F43)))," ") | K43: =IF(B43,SUM(G43,-$I$12)," ") | L43: =IF(B43,SUM(H43,-$J$12)," ") | M43: =IF(B43,POWER(K43,2)," ") | N43: =IF(B43,POWER(L43,2)," ")
A44: 7 | D44: =IF(B44,B44-$C$4," ") | E44: =IF(B44,INT(D44)," ") | F44: =IF(B44,((D44-E44)/60*100)," ") | G44: =IF(B44,C44*COS(PI()/180*(E44+F44))," ") | H44: =IF(B44,(C44*SIN(PI()/180*(E44+F44)))," ") | K44: =IF(B44,SUM(G44,-$I$12)," ") | L44: =IF(B44,SUM(H44,-$J$12)," ") | M44: =IF(B44,POWER(K44,2)," ") | N44: =IF(B44,POWER(L44,2)," ")
A45: 8 | D45: =IF(B45,B45-$C$4," ") | E45: =IF(B45,INT(D45)," ") | F45: =IF(B45,((D45-E45)/60*100)," ") | G45: =IF(B45,C45*COS(PI()/180*(E45+F45))," ") | H45: =IF(B45,(C45*SIN(PI()/180*(E45+F45)))," ") | K45: =IF(B45,SUM(G45,-$I$12)," ") | L45: =IF(B45,SUM(H45,-$J$12)," ") | M45: =IF(B45,POWER(K45,2)," ") | N45: =IF(B45,POWER(L45,2)," ")
A46: 9 | D46: =IF(B46,B46-$C$4," ") | E46: =IF(B46,INT(D46)," ") | F46: =IF(B46,((D46-E46)/60*100)," ") | G46: =IF(B46,C46*COS(PI()/180*(E46+F46))," ") | H46: =IF(B46,(C46*SIN(PI()/180*(E46+F46)))," ") | K46: =IF(B46,SUM(G46,-$I$12)," ") | L46: =IF(B46,SUM(H46,-$J$12)," ") | M46: =IF(B46,POWER(K46,2)," ") | N46: =IF(B46,POWER(L46,2)," ")
A47: 10 | D47: =IF(B47,B47-$C$4," ") | E47: =IF(B47,INT(D47)," ") | F47: =IF(B47,((D47-E47)/60*100)," ") | G47: =IF(B47,C47*COS(PI()/180*(E47+F47))," ") | H47: =IF(B47,(C47*SIN(PI()/180*(E47+F47)))," ") | K47: =IF(B47,SUM(G47,-$I$12)," ") | L47: =IF(B47,SUM(H47,-$J$12)," ") | M47: =IF(B47,POWER(K47,2)," ") | N47: =IF(B47,POWER(L47,2)," ")
A48: 11 | D48: =IF(B48,B48-$C$4," ") | E48: =IF(B48,INT(D48)," ") | F48: =IF(B48,((D48-E48)/60*100)," ") | G48: =IF(B48,C48*COS(PI()/180*(E48+F48))," ") | H48: =IF(B48,(C48*SIN(PI()/180*(E48+F48)))," ") | K48: =IF(B48,SUM(G48,-$I$12)," ") | L48: =IF(B48,SUM(H48,-$J$12)," ") | M48: =IF(B48,POWER(K48,2)," ") | N48: =IF(B48,POWER(L48,2)," ")
A49: 12 | D49: =IF(B49,B49-$C$4," ") | E49: =IF(B49,INT(D49)," ") | F49: =IF(B49,((D49-E49)/60*100)," ") | G49: =IF(B49,C49*COS(PI()/180*(E49+F49))," ") | H49: =IF(B49,(C49*SIN(PI()/180*(E49+F49)))," ") | K49: =IF(B49,SUM(G49,-$I$12)," ") | L49: =IF(B49,SUM(H49,-$J$12)," ") | M49: =IF(B49,POWER(K49,2)," ") | N49: =IF(B49,POWER(L49,2)," ")
A50: 13 | D50: =IF(B50,B50-$C$4," ") | E50: =IF(B50,INT(D50)," ") | F50: =IF(B50,((D50-E50)/60*100)," ") | G50: =IF(B50,C50*COS(PI()/180*(E50+F50))," ") | H50: =IF(B50,(C50*SIN(PI()/180*(E50+F50)))," ") | K50: =IF(B50,SUM(G50,-$I$12)," ") | L50: =IF(B50,SUM(H50,-$J$12)," ") | M50: =IF(B50,POWER(K50,2)," ") | N50: =IF(B50,POWER(L50,2)," ")
... A61: 24 | D61: =IF(B61,B61-$C$4," ") | E61: =IF(B61,INT(D61)," ") | F61: =IF(B61,((D61-E61)/60*100)," ") | G61: =IF(B61,C61*COS(PI()/180*(E61+F61))," ") | H61: =IF(B61,(C61*SIN(PI()/180*(E61+F61)))," ") | K61: =IF(B61,SUM(G61,-$I$12)," ") | L61: =IF(B61,SUM(H61,-$J$12)," ") | M61: =IF(B61,POWER(K61,2)," ") | N61: =IF(B61,POWER(L61,2)," ")

Sheet 240-9
B1: 240-9
B2: Канал | C2: курс | D2: Vпр | E2: Нпус | F2: Дпус | I2: Центр рассеивания НАР
B3: ЦУ | D3: км/ч | E3: м | F3: м
B4: НВГЦ/ЛЦУ | C4: 270 | I4: =(I12+I38)/2 -> 156.44359 | J4: =(J12+J38)/2 -> -54.62697
B5: Число КОБЭ | C5: Всего | D5: НАР 1 | E5: НАР 2 | I5: x | J5: z
C6: 44 | D6: 21 | E6: 23
A10: КОБЭ от НАР 1
A11: номер п/п | B11: азимут | C11: дальность | D11: Азимут за вычетом боевого курса | E11: градусы | F11: минуты (в сотых градуса) | G11: х | H11: z | I11: Мх | J11: Мz | K11: Хт-Мх | L11: Zт-Мz | M11: (Хт-Мх)*2 | N11: (Zт-Мz)*2 | O11: N-1 | P11: Σ(Хт-Мх)*2 | Q11: Σ(Zт-Мz)*2 | R11: (Σ(Хт-Мх)*2)/(N-1) | S11: (Σ(Zт-Мz)*2)/(N-1) | T11: Сигма X | U11: Сигма Z | V11: σX*σZ | W11: СКО КОБЭ
A12: 1 | B12: 274.4 | C12: 138 | D12: =IF(B12,B12-$C$4," ") -> 4.4 | E12: =IF(B12,INT(D12)," ") -> 4 | F12: =IF(B12,((D12-E12)/60*100)," ") -> 0.66666667 | G12: =IF(B12,C12*COS(PI()/180*(E12+F12))," ") -> 137.54251 | H12: =IF(B12,(C12*SIN(PI()/180*(E12+F12)))," ") -> 11.227497 | I12: =SUM(G12:G32)/D6 -> 187.28076 | J12: =SUM(H12:H32)/D6 -> 3.773773 | K12: =IF(B12,SUM(G12,-$I$12)," ") -> -49.738249 | L12: =IF(B12,SUM(H12,-$J$12)," ") -> 7.4537241 | M12: =IF(B12,POWER(K12,2)," ") -> 2473.8934 | N12: =IF(B12,POWER(L12,2)," ") -> 55.558003 | O12: =D6-1 -> 20 | P12: =SUM(M12:M35) -> 22707.827 | Q12: =SUM(N12:N35) -> 1641.3306 | R12: =PRODUCT(P12,1/$O$12) -> 1135.3913 | S12: =PRODUCT(Q12,1/$O$12) -> 82.066531 | T12: =SQRT(R12) -> 33.695569 | U12: =SQRT(S12) -> 9.059058 | V12: =PRODUCT(T12:U12) -> 305.25011 | W12: =SQRT(V12) -> 17.471408
A13: 2 | B13: 272.5 | C13: 140 | D13: =IF(B13,B13-$C$4," ") -> 2.5 | E13: =IF(B13,INT(D13)," ") -> 2 | F13: =IF(B13,((D13-E13)/60*100)," ") -> 0.83333333 | G13: =IF(B13,C13*COS(PI()/180*(E13+F13))," ") -> 139.82886 | H13: =IF(B13,(C13*SIN(PI()/180*(E13+F13)))," ") -> 6.9203181 | K13: =IF(B13,SUM(G13,-$I$12)," ") -> -47.451907 | L13: =IF(B13,SUM(H13,-$J$12)," ") -> 3.1465451 | M13: =IF(B13,POWER(K13,2)," ") -> 2251.6835 | N13: =IF(B13,POWER(L13,2)," ") -> 9.9007459
A14: 3 | B14: 271.1 | C14: 140 | D14: =IF(B14,B14-$C$4," ") -> 1.1 | E14: =IF(B14,INT(D14)," ") -> 1 | F14: =IF(B14,((D14-E14)/60*100)," ") -> 0.16666667 | G14: =IF(B14,C14*COS(PI()/180*(E14+F14))," ") -> 139.97098 | H14: =IF(B14,(C14*SIN(PI()/180*(E14+F14)))," ") -> 2.8505075 | K14: =IF(B14,SUM(G14,-$I$12)," ") -> -47.309786 | L14: =IF(B14,SUM(H14,-$J$12)," ") -> -0.92326554 | M14: =IF(B14,POWER(K14,2)," ") -> 2238.2159 | N14: =IF(B14,POWER(L14,2)," ") -> 0.85241926
A15: 4 | B15: 270.05 | C15: 146 | D15: =IF(B15,B15-$C$4," ") -> 0.05 | E15: =IF(B15,INT(D15)," ") -> 0 | F15: =IF(B15,((D15-E15)/60*100)," ") -> 0.083333333 | G15: =IF(B15,C15*COS(PI()/180*(E15+F15))," ") -> 145.99985 | H15: =IF(B15,(C15*SIN(PI()/180*(E15+F15)))," ") -> 0.21234832 | K15: =IF(B15,SUM(G15,-$I$12)," ") -> -41.280918 | L15: =IF(B15,SUM(H15,-$J$12)," ") -> -3.5614247 | M15: =IF(B15,POWER(K15,2)," ") -> 1704.1142 | N15: =IF(B15,POWER(L15,2)," ") -> 12.683746
A16: 5 | B16: 269.5 | C16: 150 | D16: =IF(B16,B16-$C$4," ") -> -0.5 | E16: =IF(B16,INT(D16)," ") -> -1 | F16: =IF(B16,((D16-E16)/60*100)," ") -> 0.83333333 | G16: =IF(B16,C16*COS(PI()/180*(E16+F16))," ") -> 149.99937 | H16: =IF(B16,(C16*SIN(PI()/180*(E16+F16)))," ") -> -0.4363317 | K16: =IF(B16,SUM(G16,-$I$12)," ") -> -37.281398 | L16: =IF(B16,SUM(H16,-$J$12)," ") -> -4.2101047 | M16: =IF(B16,POWER(K16,2)," ") -> 1389.9027 | N16: =IF(B16,POWER(L16,2)," ") -> 17.724982
A17: 6 | B17: 274.55 | C17: 150 | D17: =IF(B17,B17-$C$4," ") -> 4.55 | E17: =IF(B17,INT(D17)," ") -> 4 | F17: =IF(B17,((D17-E17)/60*100)," ") -> 0.91666667 | G17: =IF(B17,C17*COS(PI()/180*(E17+F17))," ") -> 149.44806 | H17: =IF(B17,(C17*SIN(PI()/180*(E17+F17)))," ") -> 12.856012 | K17: =IF(B17,SUM(G17,-$I$12)," ") -> -37.832703 | L17: =IF(B17,SUM(H17,-$J$12)," ") -> 9.0822387 | M17: =IF(B17,POWER(K17,2)," ") -> 1431.3134 | N17: =IF(B17,POWER(L17,2)," ") -> 82.48706
A18: 7 | B18: 271.2 | C18: 166 | D18: =IF(B18,B18-$C$4," ") -> 1.2 | E18: =IF(B18,INT(D18)," ") -> 1 | F18: =IF(B18,((D18-E18)/60*100)," ") -> 0.33333333 | G18: =IF(B18,C18*COS(PI()/180*(E18+F18))," ") -> 165.95505 | H18: =IF(B18,(C18*SIN(PI()/180*(E18+F18)))," ") -> 3.8626468 | K18: =IF(B18,SUM(G18,-$I$12)," ") -> -21.32571 | L18: =IF(B18,SUM(H18,-$J$12)," ") -> 0.08887376 | M18: =IF(B18,POWER(K18,2)," ") -> 454.78589 | N18: =IF(B18,POWER(L18,2)," ") -> 0.0078985452
A19: 8 | B19: 274.5 | C19: 186 | D19: =IF(B19,B19-$C$4," ") -> 4.5 | E19: =IF(B19,INT(D19)," ") -> 4 | F19: =IF(B19,((D19-E19)/60*100)," ") -> 0.83333333 | G19: =IF(B19,C19*COS(PI()/180*(E19+F19))," ") -> 185.33859 | H19: =IF(B19,(C19*SIN(PI()/180*(E19+F19)))," ") -> 15.671907 | K19: =IF(B19,SUM(G19,-$I$12)," ") -> -1.9421781 | L19: =IF(B19,SUM(H19,-$J$12)," ") -> 11.898134 | M19: =IF(B19,POWER(K19,2)," ") -> 3.7720558 | N19: =IF(B19,POWER(L19,2)," ") -> 141.5656
A20: 9 | B20: 275.2 | C20: 196 | D20: =IF(B20,B20-$C$4," ") -> 5.2 | E20: =IF(B20,INT(D20)," ") -> 5 | F20: =IF(B20,((D20-E20)/60*100)," ") -> 0.33333333 | G20: =IF(B20,C20*COS(PI()/180*(E20+F20))," ") -> 195.15147 | H20: =IF(B20,(C20*SIN(PI()/180*(E20+F20)))," ") -> 18.218173 | K20: =IF(B20,SUM(G20,-$I$12)," ") -> 7.8707112 | L20: =IF(B20,SUM(H20,-$J$12)," ") -> 14.4444 | M20: =IF(B20,POWER(K20,2)," ") -> 61.948095 | N20: =IF(B20,POWER(L20,2)," ") -> 208.64068
A21: 10 | B21: 271.3 | C21: 194 | D21: =IF(B21,B21-$C$4," ") -> 1.3 | E21: =IF(B21,INT(D21)," ") -> 1 | F21: =IF(B21,((D21-E21)/60*100)," ") -> 0.5 | G21: =IF(B21,C21*COS(PI()/180*(E21+F21))," ") -> 193.93352 | H21: =IF(B21,(C21*SIN(PI()/180*(E21+F21)))," ") -> 5.078328 | K21: =IF(B21,SUM(G21,-$I$12)," ") -> 6.6527573 | L21: =IF(B21,SUM(H21,-$J$12)," ") -> 1.304555 | M21: =IF(B21,POWER(K21,2)," ") -> 44.25918 | N21: =IF(B21,POWER(L21,2)," ") -> 1.7018637
